test_create_issue (create-issue.CreateIssue) ... FAIL
test_search_issue (search-issue.SearchIssue) ... FAIL
ERROR
test_update_issue (update-issue.UpdateIssue) ... ERROR

======================================================================
ERROR: test_search_issue (search-issue.SearchIssue)
----------------------------------------------------------------------
Traceback (most recent call last):
  File "test-cases/firefox/search-issue.py", line 137, in tearDown
    self.driver.quit()
  File "D:\Python27\lib\site-packages\selenium\webdriver\firefox\webdriver.py", line 67, in quit
    RemoteWebDriver.quit(self)
  File "D:\Python27\lib\site-packages\selenium\webdriver\remote\webdriver.py", line 455, in quit
    self.execute(Command.QUIT)
  File "D:\Python27\lib\site-packages\selenium\webdriver\remote\webdriver.py", line 171, in execute
    response = self.command_executor.execute(driver_command, params)
  File "D:\Python27\lib\site-packages\selenium\webdriver\remote\remote_connection.py", line 349, in execute
    return self._request(command_info[0], url, body=data)
  File "D:\Python27\lib\site-packages\selenium\webdriver\remote\remote_connection.py", line 379, in _request
    self._conn.request(method, parsed_url.path, body, headers)
  File "D:\Python27\lib\httplib.py", line 995, in request
    self._send_request(method, url, body, headers)
  File "D:\Python27\lib\httplib.py", line 1023, in _send_request
    self.putrequest(method, url, **skips)
  File "D:\Python27\lib\httplib.py", line 886, in putrequest
    raise CannotSendRequest()
CannotSendRequest

======================================================================
ERROR: test_update_issue (update-issue.UpdateIssue)
----------------------------------------------------------------------
Traceback (most recent call last):
  File "test-cases/firefox/update-issue.py", line 38, in test_update_issue
    driver.get(self.base_url + "/login")
  File "D:\Python27\lib\site-packages\selenium\webdriver\remote\webdriver.py", line 185, in get
    self.execute(Command.GET, {'url': url})
  File "D:\Python27\lib\site-packages\selenium\webdriver\remote\webdriver.py", line 171, in execute
    response = self.command_executor.execute(driver_command, params)
  File "D:\Python27\lib\site-packages\selenium\webdriver\remote\remote_connection.py", line 349, in execute
    return self._request(command_info[0], url, body=data)
  File "D:\Python27\lib\site-packages\selenium\webdriver\remote\remote_connection.py", line 380, in _request
    resp = self._conn.getresponse()
  File "D:\Python27\lib\httplib.py", line 1067, in getresponse
    response.begin()
  File "D:\Python27\lib\httplib.py", line 409, in begin
    version, status, reason = self._read_status()
  File "D:\Python27\lib\httplib.py", line 373, in _read_status
    raise BadStatusLine(line)
BadStatusLine: ''

======================================================================
FAIL: test_create_issue (create-issue.CreateIssue)
----------------------------------------------------------------------
Traceback (most recent call last):
  File "test-cases/firefox/create-issue.py", line 45, in test_create_issue
    # else: self.fail("time out")
AssertionError: time out

======================================================================
FAIL: test_search_issue (search-issue.SearchIssue)
----------------------------------------------------------------------
Traceback (most recent call last):
  File "test-cases/firefox/search-issue.py", line 44, in test_search_issue
    else: self.fail("time out")
AssertionError: time out

----------------------------------------------------------------------
Ran 3 tests in 540.498s

FAILED (failures=2, errors=2)
